2023-05-04 18:03:05,082 snap7.client creating snap7 client
2023-05-04 18:03:05,083 _plc_.client Connection with PLC 192.168.0.10 started
2023-05-04 18:03:05,284 _plc_.client Подключение к контроллеру 192.168.0.10...
2023-05-04 18:03:05,284 snap7.client connecting to 192.168.0.10:102 rack 0 slot 1
2023-05-04 18:03:05,761 snap7.common b' TCP : Unreachable peer'
2023-05-04 18:03:05,780 _plc_.client Не удалось подключиться к контроллеру: 192.168.0.10
Ошибка b' TCP : Unreachable peer' Traceback (most recent call last):
  File "D:\Work\DMU85\PLC_CV\python\plc.py", line 76, in run
    self.snap7client.connect(self.plc_ip, 0, 1)
  File "D:\Work\DMU85\PLC_CV\venv\lib\site-packages\snap7\client\__init__.py", line 24, in f
    check_error(code, context="client")
  File "D:\Work\DMU85\PLC_CV\venv\lib\site-packages\snap7\common.py", line 89, in check_error
    raise RuntimeError(error)
RuntimeError: b' TCP : Unreachable peer'

2023-05-04 18:04:05,952 _plc_.client Подключение к контроллеру 192.168.0.10...
2023-05-04 18:04:06,261 snap7.common b' TCP : Unreachable peer'
2023-05-04 18:04:06,261 _plc_.client Не удалось подключиться к контроллеру: 192.168.0.10
Ошибка b' TCP : Unreachable peer' Traceback (most recent call last):
  File "D:\Work\DMU85\PLC_CV\python\plc.py", line 76, in run
    self.snap7client.connect(self.plc_ip, 0, 1)
  File "D:\Work\DMU85\PLC_CV\venv\lib\site-packages\snap7\client\__init__.py", line 24, in f
    check_error(code, context="client")
  File "D:\Work\DMU85\PLC_CV\venv\lib\site-packages\snap7\common.py", line 89, in check_error
    raise RuntimeError(error)
RuntimeError: b' TCP : Unreachable peer'

2023-05-04 18:04:27,260 snap7.client creating snap7 client
2023-05-04 18:04:27,262 _plc_.client Connection with PLC 192.168.0.10 started
2023-05-04 18:04:27,463 _plc_.client Подключение к контроллеру 192.168.0.10...
2023-05-04 18:04:27,464 snap7.client connecting to 192.168.0.10:102 rack 0 slot 1
2023-05-04 18:04:27,753 snap7.common b' TCP : Unreachable peer'
2023-05-04 18:04:27,754 _plc_.client Не удалось подключиться к контроллеру: 192.168.0.10
Ошибка b' TCP : Unreachable peer' Traceback (most recent call last):
  File "D:\Work\DMU85\PLC_CV\python\plc.py", line 76, in run
    self.snap7client.connect(self.plc_ip, 0, 1)
  File "D:\Work\DMU85\PLC_CV\venv\lib\site-packages\snap7\client\__init__.py", line 24, in f
    check_error(code, context="client")
  File "D:\Work\DMU85\PLC_CV\venv\lib\site-packages\snap7\common.py", line 89, in check_error
    raise RuntimeError(error)
RuntimeError: b' TCP : Unreachable peer'

2023-05-04 18:05:11,724 snap7.client creating snap7 client
2023-05-04 18:05:11,725 _plc_.client Connection with PLC 192.168.0.10 started
2023-05-04 18:05:11,926 _plc_.client Подключение к контроллеру 192.168.0.10...
2023-05-04 18:05:11,927 snap7.client connecting to 192.168.0.10:102 rack 0 slot 1
2023-05-04 18:05:12,256 snap7.common b' TCP : Unreachable peer'
2023-05-04 18:05:12,258 _plc_.client Не удалось подключиться к контроллеру: 192.168.0.10
Ошибка b' TCP : Unreachable peer' Traceback (most recent call last):
  File "D:\Work\DMU85\PLC_CV\python\plc.py", line 76, in run
    self.snap7client.connect(self.plc_ip, 0, 1)
  File "D:\Work\DMU85\PLC_CV\venv\lib\site-packages\snap7\client\__init__.py", line 24, in f
    check_error(code, context="client")
  File "D:\Work\DMU85\PLC_CV\venv\lib\site-packages\snap7\common.py", line 89, in check_error
    raise RuntimeError(error)
RuntimeError: b' TCP : Unreachable peer'

2023-05-04 18:05:27,924 _plc_.client Подключение к контроллеру 192.168.0.10...
2023-05-04 18:05:28,256 snap7.common b' TCP : Unreachable peer'
2023-05-04 18:05:28,257 _plc_.client Не удалось подключиться к контроллеру: 192.168.0.10
Ошибка b' TCP : Unreachable peer' Traceback (most recent call last):
  File "D:\Work\DMU85\PLC_CV\python\plc.py", line 76, in run
    self.snap7client.connect(self.plc_ip, 0, 1)
  File "D:\Work\DMU85\PLC_CV\venv\lib\site-packages\snap7\client\__init__.py", line 24, in f
    check_error(code, context="client")
  File "D:\Work\DMU85\PLC_CV\venv\lib\site-packages\snap7\common.py", line 89, in check_error
    raise RuntimeError(error)
RuntimeError: b' TCP : Unreachable peer'

2023-05-04 18:06:12,439 _plc_.client Подключение к контроллеру 192.168.0.10...
2023-05-04 18:06:12,756 snap7.common b' TCP : Unreachable peer'
2023-05-04 18:06:12,757 _plc_.client Не удалось подключиться к контроллеру: 192.168.0.10
Ошибка b' TCP : Unreachable peer' Traceback (most recent call last):
  File "D:\Work\DMU85\PLC_CV\python\plc.py", line 76, in run
    self.snap7client.connect(self.plc_ip, 0, 1)
  File "D:\Work\DMU85\PLC_CV\venv\lib\site-packages\snap7\client\__init__.py", line 24, in f
    check_error(code, context="client")
  File "D:\Work\DMU85\PLC_CV\venv\lib\site-packages\snap7\common.py", line 89, in check_error
    raise RuntimeError(error)
RuntimeError: b' TCP : Unreachable peer'

2023-05-04 18:12:30,578 snap7.client creating snap7 client
2023-05-04 18:13:16,643 snap7.client creating snap7 client
2023-05-04 18:13:16,661 vision.main Techvision started
2023-05-04 18:13:16,661 _plc_.client Connection with PLC 192.168.0.10 started
2023-05-04 18:13:16,863 _plc_.client Подключение к контроллеру 192.168.0.10...
2023-05-04 18:13:16,864 snap7.client connecting to 192.168.0.10:102 rack 0 slot 1
2023-05-04 18:13:17,250 snap7.common b' TCP : Unreachable peer'
2023-05-04 18:13:17,253 _plc_.client Не удалось подключиться к контроллеру: 192.168.0.10
Ошибка b' TCP : Unreachable peer' Traceback (most recent call last):
  File "D:\Work\DMU85\PLC_CV\python\plc.py", line 76, in run
    self.snap7client.connect(self.plc_ip, 0, 1)
  File "D:\Work\DMU85\PLC_CV\venv\lib\site-packages\snap7\client\__init__.py", line 24, in f
    check_error(code, context="client")
  File "D:\Work\DMU85\PLC_CV\venv\lib\site-packages\snap7\common.py", line 89, in check_error
    raise RuntimeError(error)
RuntimeError: b' TCP : Unreachable peer'

2023-05-04 18:14:17,443 _plc_.client Подключение к контроллеру 192.168.0.10...
2023-05-04 18:14:17,759 snap7.common b' TCP : Unreachable peer'
2023-05-04 18:14:17,760 _plc_.client Не удалось подключиться к контроллеру: 192.168.0.10
Ошибка b' TCP : Unreachable peer' Traceback (most recent call last):
  File "D:\Work\DMU85\PLC_CV\python\plc.py", line 76, in run
    self.snap7client.connect(self.plc_ip, 0, 1)
  File "D:\Work\DMU85\PLC_CV\venv\lib\site-packages\snap7\client\__init__.py", line 24, in f
    check_error(code, context="client")
  File "D:\Work\DMU85\PLC_CV\venv\lib\site-packages\snap7\common.py", line 89, in check_error
    raise RuntimeError(error)
RuntimeError: b' TCP : Unreachable peer'

2023-05-04 18:15:05,416 snap7.client creating snap7 client
2023-05-04 18:15:05,426 vision.main Techvision started
2023-05-04 18:15:05,428 _plc_.client Connection with PLC 192.168.0.10 started
2023-05-04 18:15:05,631 _plc_.client Подключение к контроллеру 192.168.0.10...
2023-05-04 18:15:05,631 snap7.client connecting to 192.168.0.10:102 rack 0 slot 1
2023-05-04 18:15:05,763 snap7.common b' TCP : Unreachable peer'
2023-05-04 18:15:05,765 _plc_.client Не удалось подключиться к контроллеру: 192.168.0.10
Ошибка b' TCP : Unreachable peer' Traceback (most recent call last):
  File "D:\Work\DMU85\PLC_CV\python\plc.py", line 76, in run
    self.snap7client.connect(self.plc_ip, 0, 1)
  File "D:\Work\DMU85\PLC_CV\venv\lib\site-packages\snap7\client\__init__.py", line 24, in f
    check_error(code, context="client")
  File "D:\Work\DMU85\PLC_CV\venv\lib\site-packages\snap7\common.py", line 89, in check_error
    raise RuntimeError(error)
RuntimeError: b' TCP : Unreachable peer'

2023-05-04 18:15:51,370 snap7.client creating snap7 client
2023-05-04 18:15:51,382 vision.main Techvision started
2023-05-04 18:15:51,382 _plc_.client Connection with PLC 192.168.0.10 started
2023-05-04 18:15:51,584 _plc_.client Подключение к контроллеру 192.168.0.10...
2023-05-04 18:15:51,586 snap7.client connecting to 192.168.0.10:102 rack 0 slot 1
2023-05-04 18:15:51,753 snap7.common b' TCP : Unreachable peer'
2023-05-04 18:15:51,756 _plc_.client Не удалось подключиться к контроллеру: 192.168.0.10
Ошибка b' TCP : Unreachable peer' Traceback (most recent call last):
  File "D:\Work\DMU85\PLC_CV\python\plc.py", line 76, in run
    self.snap7client.connect(self.plc_ip, 0, 1)
  File "D:\Work\DMU85\PLC_CV\venv\lib\site-packages\snap7\client\__init__.py", line 24, in f
    check_error(code, context="client")
  File "D:\Work\DMU85\PLC_CV\venv\lib\site-packages\snap7\common.py", line 89, in check_error
    raise RuntimeError(error)
RuntimeError: b' TCP : Unreachable peer'

2023-05-04 18:16:51,953 _plc_.client Подключение к контроллеру 192.168.0.10...
2023-05-04 18:16:52,251 snap7.common b' TCP : Unreachable peer'
2023-05-04 18:16:52,253 _plc_.client Не удалось подключиться к контроллеру: 192.168.0.10
Ошибка b' TCP : Unreachable peer' Traceback (most recent call last):
  File "D:\Work\DMU85\PLC_CV\python\plc.py", line 76, in run
    self.snap7client.connect(self.plc_ip, 0, 1)
  File "D:\Work\DMU85\PLC_CV\venv\lib\site-packages\snap7\client\__init__.py", line 24, in f
    check_error(code, context="client")
  File "D:\Work\DMU85\PLC_CV\venv\lib\site-packages\snap7\common.py", line 89, in check_error
    raise RuntimeError(error)
RuntimeError: b' TCP : Unreachable peer'

2023-05-04 18:18:22,926 snap7.client creating snap7 client
2023-05-04 18:18:22,938 vision.main Techvision started
2023-05-04 18:18:22,939 _plc_.client Connection with PLC 192.168.0.10 started
2023-05-04 18:18:23,141 _plc_.client Подключение к контроллеру 192.168.0.10...
2023-05-04 18:18:23,142 snap7.client connecting to 192.168.0.10:102 rack 0 slot 1
2023-05-04 18:18:23,251 snap7.common b' TCP : Unreachable peer'
2023-05-04 18:18:23,257 _plc_.client Не удалось подключиться к контроллеру: 192.168.0.10
Ошибка b' TCP : Unreachable peer' Traceback (most recent call last):
  File "D:\Work\DMU85\PLC_CV\python\plc.py", line 76, in run
    self.snap7client.connect(self.plc_ip, 0, 1)
  File "D:\Work\DMU85\PLC_CV\venv\lib\site-packages\snap7\client\__init__.py", line 24, in f
    check_error(code, context="client")
  File "D:\Work\DMU85\PLC_CV\venv\lib\site-packages\snap7\common.py", line 89, in check_error
    raise RuntimeError(error)
RuntimeError: b' TCP : Unreachable peer'

2023-05-04 18:19:09,640 snap7.client creating snap7 client
2023-05-04 18:19:09,651 vision.main Techvision started
2023-05-04 18:19:09,651 _plc_.client Connection with PLC 192.168.0.10 started
2023-05-04 18:19:09,853 _plc_.client Подключение к контроллеру 192.168.0.10...
2023-05-04 18:19:09,857 snap7.client connecting to 192.168.0.10:102 rack 0 slot 1
2023-05-04 18:19:10,251 snap7.common b' TCP : Unreachable peer'
2023-05-04 18:19:10,252 _plc_.client Не удалось подключиться к контроллеру: 192.168.0.10
Ошибка b' TCP : Unreachable peer' Traceback (most recent call last):
  File "D:\Work\DMU85\PLC_CV\python\plc.py", line 76, in run
    self.snap7client.connect(self.plc_ip, 0, 1)
  File "D:\Work\DMU85\PLC_CV\venv\lib\site-packages\snap7\client\__init__.py", line 24, in f
    check_error(code, context="client")
  File "D:\Work\DMU85\PLC_CV\venv\lib\site-packages\snap7\common.py", line 89, in check_error
    raise RuntimeError(error)
RuntimeError: b' TCP : Unreachable peer'

2023-05-04 18:19:36,540 snap7.client creating snap7 client
2023-05-04 18:19:36,552 vision.main Techvision started
2023-05-04 18:19:36,552 _plc_.client Connection with PLC 192.168.0.10 started
2023-05-04 18:19:36,756 _plc_.client Подключение к контроллеру 192.168.0.10...
2023-05-04 18:19:36,756 snap7.client connecting to 192.168.0.10:102 rack 0 slot 1
2023-05-04 18:19:37,261 snap7.common b' TCP : Unreachable peer'
2023-05-04 18:19:37,264 _plc_.client Не удалось подключиться к контроллеру: 192.168.0.10
Ошибка b' TCP : Unreachable peer' Traceback (most recent call last):
  File "D:\Work\DMU85\PLC_CV\python\plc.py", line 76, in run
    self.snap7client.connect(self.plc_ip, 0, 1)
  File "D:\Work\DMU85\PLC_CV\venv\lib\site-packages\snap7\client\__init__.py", line 24, in f
    check_error(code, context="client")
  File "D:\Work\DMU85\PLC_CV\venv\lib\site-packages\snap7\common.py", line 89, in check_error
    raise RuntimeError(error)
RuntimeError: b' TCP : Unreachable peer'

2023-05-04 18:20:37,449 _plc_.client Подключение к контроллеру 192.168.0.10...
2023-05-04 18:20:37,758 snap7.common b' TCP : Unreachable peer'
2023-05-04 18:20:37,759 _plc_.client Не удалось подключиться к контроллеру: 192.168.0.10
Ошибка b' TCP : Unreachable peer' Traceback (most recent call last):
  File "D:\Work\DMU85\PLC_CV\python\plc.py", line 76, in run
    self.snap7client.connect(self.plc_ip, 0, 1)
  File "D:\Work\DMU85\PLC_CV\venv\lib\site-packages\snap7\client\__init__.py", line 24, in f
    check_error(code, context="client")
  File "D:\Work\DMU85\PLC_CV\venv\lib\site-packages\snap7\common.py", line 89, in check_error
    raise RuntimeError(error)
RuntimeError: b' TCP : Unreachable peer'

2023-05-04 18:21:00,663 snap7.client creating snap7 client
2023-05-04 18:21:00,675 vision.main Techvision started
2023-05-04 18:21:00,676 _plc_.client Connection with PLC 192.168.0.10 started
2023-05-04 18:21:00,878 _plc_.client Подключение к контроллеру 192.168.0.10...
2023-05-04 18:21:00,879 snap7.client connecting to 192.168.0.10:102 rack 0 slot 1
2023-05-04 18:21:01,253 snap7.common b' TCP : Unreachable peer'
2023-05-04 18:21:01,255 _plc_.client Не удалось подключиться к контроллеру: 192.168.0.10
Ошибка b' TCP : Unreachable peer' Traceback (most recent call last):
  File "D:\Work\DMU85\PLC_CV\python\plc.py", line 76, in run
    self.snap7client.connect(self.plc_ip, 0, 1)
  File "D:\Work\DMU85\PLC_CV\venv\lib\site-packages\snap7\client\__init__.py", line 24, in f
    check_error(code, context="client")
  File "D:\Work\DMU85\PLC_CV\venv\lib\site-packages\snap7\common.py", line 89, in check_error
    raise RuntimeError(error)
RuntimeError: b' TCP : Unreachable peer'

2023-05-04 18:22:01,444 _plc_.client Подключение к контроллеру 192.168.0.10...
2023-05-04 18:22:01,762 snap7.common b' TCP : Unreachable peer'
2023-05-04 18:22:01,763 _plc_.client Не удалось подключиться к контроллеру: 192.168.0.10
Ошибка b' TCP : Unreachable peer' Traceback (most recent call last):
  File "D:\Work\DMU85\PLC_CV\python\plc.py", line 76, in run
    self.snap7client.connect(self.plc_ip, 0, 1)
  File "D:\Work\DMU85\PLC_CV\venv\lib\site-packages\snap7\client\__init__.py", line 24, in f
    check_error(code, context="client")
  File "D:\Work\DMU85\PLC_CV\venv\lib\site-packages\snap7\common.py", line 89, in check_error
    raise RuntimeError(error)
RuntimeError: b' TCP : Unreachable peer'

2023-05-04 18:22:47,717 snap7.client creating snap7 client
2023-05-04 18:22:47,729 vision.main Techvision started
2023-05-04 18:22:47,729 _plc_.client Connection with PLC 192.168.0.10 started
2023-05-04 18:22:47,930 _plc_.client Подключение к контроллеру 192.168.0.10...
2023-05-04 18:22:47,931 snap7.client connecting to 192.168.0.10:102 rack 0 slot 1
2023-05-04 18:22:48,252 snap7.common b' TCP : Unreachable peer'
2023-05-04 18:22:48,253 _plc_.client Не удалось подключиться к контроллеру: 192.168.0.10
Ошибка b' TCP : Unreachable peer' Traceback (most recent call last):
  File "D:\Work\DMU85\PLC_CV\python\plc.py", line 76, in run
    self.snap7client.connect(self.plc_ip, 0, 1)
  File "D:\Work\DMU85\PLC_CV\venv\lib\site-packages\snap7\client\__init__.py", line 24, in f
    check_error(code, context="client")
  File "D:\Work\DMU85\PLC_CV\venv\lib\site-packages\snap7\common.py", line 89, in check_error
    raise RuntimeError(error)
RuntimeError: b' TCP : Unreachable peer'

2023-05-04 18:23:48,254 _plc_.client Подключение к контроллеру 192.168.0.10...
2023-05-04 18:23:48,759 snap7.common b' TCP : Unreachable peer'
2023-05-04 18:23:48,760 _plc_.client Не удалось подключиться к контроллеру: 192.168.0.10
Ошибка b' TCP : Unreachable peer' Traceback (most recent call last):
  File "D:\Work\DMU85\PLC_CV\python\plc.py", line 76, in run
    self.snap7client.connect(self.plc_ip, 0, 1)
  File "D:\Work\DMU85\PLC_CV\venv\lib\site-packages\snap7\client\__init__.py", line 24, in f
    check_error(code, context="client")
  File "D:\Work\DMU85\PLC_CV\venv\lib\site-packages\snap7\common.py", line 89, in check_error
    raise RuntimeError(error)
RuntimeError: b' TCP : Unreachable peer'

2023-05-04 18:24:29,749 snap7.client creating snap7 client
2023-05-04 18:24:29,762 vision.main Techvision started
2023-05-04 18:24:29,762 _plc_.client Connection with PLC 192.168.0.10 started
2023-05-04 18:24:29,963 _plc_.client Подключение к контроллеру 192.168.0.10...
2023-05-04 18:24:29,963 snap7.client connecting to 192.168.0.10:102 rack 0 slot 1
2023-05-04 18:24:30,258 snap7.common b' TCP : Unreachable peer'
2023-05-04 18:24:30,261 _plc_.client Не удалось подключиться к контроллеру: 192.168.0.10
Ошибка b' TCP : Unreachable peer' Traceback (most recent call last):
  File "D:\Work\DMU85\PLC_CV\python\plc.py", line 76, in run
    self.snap7client.connect(self.plc_ip, 0, 1)
  File "D:\Work\DMU85\PLC_CV\venv\lib\site-packages\snap7\client\__init__.py", line 24, in f
    check_error(code, context="client")
  File "D:\Work\DMU85\PLC_CV\venv\lib\site-packages\snap7\common.py", line 89, in check_error
    raise RuntimeError(error)
RuntimeError: b' TCP : Unreachable peer'

2023-05-04 18:24:48,942 _plc_.client Подключение к контроллеру 192.168.0.10...
2023-05-04 18:24:49,264 snap7.common b' TCP : Unreachable peer'
2023-05-04 18:24:49,265 _plc_.client Не удалось подключиться к контроллеру: 192.168.0.10
Ошибка b' TCP : Unreachable peer' Traceback (most recent call last):
  File "D:\Work\DMU85\PLC_CV\python\plc.py", line 76, in run
    self.snap7client.connect(self.plc_ip, 0, 1)
  File "D:\Work\DMU85\PLC_CV\venv\lib\site-packages\snap7\client\__init__.py", line 24, in f
    check_error(code, context="client")
  File "D:\Work\DMU85\PLC_CV\venv\lib\site-packages\snap7\common.py", line 89, in check_error
    raise RuntimeError(error)
RuntimeError: b' TCP : Unreachable peer'

2023-05-04 18:25:49,448 _plc_.client Подключение к контроллеру 192.168.0.10...
2023-05-04 18:25:49,755 snap7.common b' TCP : Unreachable peer'
2023-05-04 18:25:49,756 _plc_.client Не удалось подключиться к контроллеру: 192.168.0.10
Ошибка b' TCP : Unreachable peer' Traceback (most recent call last):
  File "D:\Work\DMU85\PLC_CV\python\plc.py", line 76, in run
    self.snap7client.connect(self.plc_ip, 0, 1)
  File "D:\Work\DMU85\PLC_CV\venv\lib\site-packages\snap7\client\__init__.py", line 24, in f
    check_error(code, context="client")
  File "D:\Work\DMU85\PLC_CV\venv\lib\site-packages\snap7\common.py", line 89, in check_error
    raise RuntimeError(error)
RuntimeError: b' TCP : Unreachable peer'

2023-05-04 18:26:49,955 _plc_.client Подключение к контроллеру 192.168.0.10...
2023-05-04 18:26:50,260 snap7.common b' TCP : Unreachable peer'
2023-05-04 18:26:50,261 _plc_.client Не удалось подключиться к контроллеру: 192.168.0.10
Ошибка b' TCP : Unreachable peer' Traceback (most recent call last):
  File "D:\Work\DMU85\PLC_CV\python\plc.py", line 76, in run
    self.snap7client.connect(self.plc_ip, 0, 1)
  File "D:\Work\DMU85\PLC_CV\venv\lib\site-packages\snap7\client\__init__.py", line 24, in f
    check_error(code, context="client")
  File "D:\Work\DMU85\PLC_CV\venv\lib\site-packages\snap7\common.py", line 89, in check_error
    raise RuntimeError(error)
RuntimeError: b' TCP : Unreachable peer'

2023-05-04 18:27:50,460 _plc_.client Подключение к контроллеру 192.168.0.10...
2023-05-04 18:27:50,758 snap7.common b' TCP : Unreachable peer'
2023-05-04 18:27:50,758 _plc_.client Не удалось подключиться к контроллеру: 192.168.0.10
Ошибка b' TCP : Unreachable peer' Traceback (most recent call last):
  File "D:\Work\DMU85\PLC_CV\python\plc.py", line 76, in run
    self.snap7client.connect(self.plc_ip, 0, 1)
  File "D:\Work\DMU85\PLC_CV\venv\lib\site-packages\snap7\client\__init__.py", line 24, in f
    check_error(code, context="client")
  File "D:\Work\DMU85\PLC_CV\venv\lib\site-packages\snap7\common.py", line 89, in check_error
    raise RuntimeError(error)
RuntimeError: b' TCP : Unreachable peer'

2023-05-04 18:28:50,930 _plc_.client Подключение к контроллеру 192.168.0.10...
2023-05-04 18:28:51,258 snap7.common b' TCP : Unreachable peer'
2023-05-04 18:28:51,259 _plc_.client Не удалось подключиться к контроллеру: 192.168.0.10
Ошибка b' TCP : Unreachable peer' Traceback (most recent call last):
  File "D:\Work\DMU85\PLC_CV\python\plc.py", line 76, in run
    self.snap7client.connect(self.plc_ip, 0, 1)
  File "D:\Work\DMU85\PLC_CV\venv\lib\site-packages\snap7\client\__init__.py", line 24, in f
    check_error(code, context="client")
  File "D:\Work\DMU85\PLC_CV\venv\lib\site-packages\snap7\common.py", line 89, in check_error
    raise RuntimeError(error)
RuntimeError: b' TCP : Unreachable peer'

2023-05-04 18:29:51,439 _plc_.client Подключение к контроллеру 192.168.0.10...
2023-05-04 18:29:51,762 snap7.common b' TCP : Unreachable peer'
2023-05-04 18:29:51,763 _plc_.client Не удалось подключиться к контроллеру: 192.168.0.10
Ошибка b' TCP : Unreachable peer' Traceback (most recent call last):
  File "D:\Work\DMU85\PLC_CV\python\plc.py", line 76, in run
    self.snap7client.connect(self.plc_ip, 0, 1)
  File "D:\Work\DMU85\PLC_CV\venv\lib\site-packages\snap7\client\__init__.py", line 24, in f
    check_error(code, context="client")
  File "D:\Work\DMU85\PLC_CV\venv\lib\site-packages\snap7\common.py", line 89, in check_error
    raise RuntimeError(error)
RuntimeError: b' TCP : Unreachable peer'

2023-05-04 18:30:51,945 _plc_.client Подключение к контроллеру 192.168.0.10...
2023-05-04 18:30:52,271 snap7.common b' TCP : Unreachable peer'
2023-05-04 18:30:52,271 _plc_.client Не удалось подключиться к контроллеру: 192.168.0.10
Ошибка b' TCP : Unreachable peer' Traceback (most recent call last):
  File "D:\Work\DMU85\PLC_CV\python\plc.py", line 76, in run
    self.snap7client.connect(self.plc_ip, 0, 1)
  File "D:\Work\DMU85\PLC_CV\venv\lib\site-packages\snap7\client\__init__.py", line 24, in f
    check_error(code, context="client")
  File "D:\Work\DMU85\PLC_CV\venv\lib\site-packages\snap7\common.py", line 89, in check_error
    raise RuntimeError(error)
RuntimeError: b' TCP : Unreachable peer'

2023-05-04 18:31:52,452 _plc_.client Подключение к контроллеру 192.168.0.10...
2023-05-04 18:31:52,761 snap7.common b' TCP : Unreachable peer'
2023-05-04 18:31:52,763 _plc_.client Не удалось подключиться к контроллеру: 192.168.0.10
Ошибка b' TCP : Unreachable peer' Traceback (most recent call last):
  File "D:\Work\DMU85\PLC_CV\python\plc.py", line 76, in run
    self.snap7client.connect(self.plc_ip, 0, 1)
  File "D:\Work\DMU85\PLC_CV\venv\lib\site-packages\snap7\client\__init__.py", line 24, in f
    check_error(code, context="client")
  File "D:\Work\DMU85\PLC_CV\venv\lib\site-packages\snap7\common.py", line 89, in check_error
    raise RuntimeError(error)
RuntimeError: b' TCP : Unreachable peer'

2023-05-04 18:32:52,940 _plc_.client Подключение к контроллеру 192.168.0.10...
2023-05-04 18:32:53,251 snap7.common b' TCP : Unreachable peer'
2023-05-04 18:32:53,253 _plc_.client Не удалось подключиться к контроллеру: 192.168.0.10
Ошибка b' TCP : Unreachable peer' Traceback (most recent call last):
  File "D:\Work\DMU85\PLC_CV\python\plc.py", line 76, in run
    self.snap7client.connect(self.plc_ip, 0, 1)
  File "D:\Work\DMU85\PLC_CV\venv\lib\site-packages\snap7\client\__init__.py", line 24, in f
    check_error(code, context="client")
  File "D:\Work\DMU85\PLC_CV\venv\lib\site-packages\snap7\common.py", line 89, in check_error
    raise RuntimeError(error)
RuntimeError: b' TCP : Unreachable peer'

2023-05-04 18:33:53,436 _plc_.client Подключение к контроллеру 192.168.0.10...
2023-05-04 18:33:53,764 snap7.common b' TCP : Unreachable peer'
2023-05-04 18:33:53,765 _plc_.client Не удалось подключиться к контроллеру: 192.168.0.10
Ошибка b' TCP : Unreachable peer' Traceback (most recent call last):
  File "D:\Work\DMU85\PLC_CV\python\plc.py", line 76, in run
    self.snap7client.connect(self.plc_ip, 0, 1)
  File "D:\Work\DMU85\PLC_CV\venv\lib\site-packages\snap7\client\__init__.py", line 24, in f
    check_error(code, context="client")
  File "D:\Work\DMU85\PLC_CV\venv\lib\site-packages\snap7\common.py", line 89, in check_error
    raise RuntimeError(error)
RuntimeError: b' TCP : Unreachable peer'

2023-05-04 18:34:53,964 _plc_.client Подключение к контроллеру 192.168.0.10...
2023-05-04 18:34:54,258 snap7.common b' TCP : Unreachable peer'
2023-05-04 18:34:54,259 _plc_.client Не удалось подключиться к контроллеру: 192.168.0.10
Ошибка b' TCP : Unreachable peer' Traceback (most recent call last):
  File "D:\Work\DMU85\PLC_CV\python\plc.py", line 76, in run
    self.snap7client.connect(self.plc_ip, 0, 1)
  File "D:\Work\DMU85\PLC_CV\venv\lib\site-packages\snap7\client\__init__.py", line 24, in f
    check_error(code, context="client")
  File "D:\Work\DMU85\PLC_CV\venv\lib\site-packages\snap7\common.py", line 89, in check_error
    raise RuntimeError(error)
RuntimeError: b' TCP : Unreachable peer'

2023-05-04 18:35:54,266 _plc_.client Подключение к контроллеру 192.168.0.10...
2023-05-04 18:35:54,760 snap7.common b' TCP : Unreachable peer'
2023-05-04 18:35:54,761 _plc_.client Не удалось подключиться к контроллеру: 192.168.0.10
Ошибка b' TCP : Unreachable peer' Traceback (most recent call last):
  File "D:\Work\DMU85\PLC_CV\python\plc.py", line 76, in run
    self.snap7client.connect(self.plc_ip, 0, 1)
  File "D:\Work\DMU85\PLC_CV\venv\lib\site-packages\snap7\client\__init__.py", line 24, in f
    check_error(code, context="client")
  File "D:\Work\DMU85\PLC_CV\venv\lib\site-packages\snap7\common.py", line 89, in check_error
    raise RuntimeError(error)
RuntimeError: b' TCP : Unreachable peer'

2023-05-04 18:36:42,388 snap7.client creating snap7 client
2023-05-04 18:36:42,400 vision.main Techvision started
2023-05-04 18:36:42,400 _plc_.client Connection with PLC 192.168.0.10 started
2023-05-04 18:36:42,603 _plc_.client Подключение к контроллеру 192.168.0.10...
2023-05-04 18:36:42,603 snap7.client connecting to 192.168.0.10:102 rack 0 slot 1
2023-05-04 18:36:42,753 snap7.common b' TCP : Unreachable peer'
2023-05-04 18:36:42,756 _plc_.client Не удалось подключиться к контроллеру: 192.168.0.10
Ошибка b' TCP : Unreachable peer' Traceback (most recent call last):
  File "D:\Work\DMU85\PLC_CV\python\plc.py", line 76, in run
    self.snap7client.connect(self.plc_ip, 0, 1)
  File "D:\Work\DMU85\PLC_CV\venv\lib\site-packages\snap7\client\__init__.py", line 24, in f
    check_error(code, context="client")
  File "D:\Work\DMU85\PLC_CV\venv\lib\site-packages\snap7\common.py", line 89, in check_error
    raise RuntimeError(error)
RuntimeError: b' TCP : Unreachable peer'

2023-05-04 18:36:54,960 _plc_.client Подключение к контроллеру 192.168.0.10...
2023-05-04 18:36:55,261 snap7.common b' TCP : Unreachable peer'
2023-05-04 18:36:55,262 _plc_.client Не удалось подключиться к контроллеру: 192.168.0.10
Ошибка b' TCP : Unreachable peer' Traceback (most recent call last):
  File "D:\Work\DMU85\PLC_CV\python\plc.py", line 76, in run
    self.snap7client.connect(self.plc_ip, 0, 1)
  File "D:\Work\DMU85\PLC_CV\venv\lib\site-packages\snap7\client\__init__.py", line 24, in f
    check_error(code, context="client")
  File "D:\Work\DMU85\PLC_CV\venv\lib\site-packages\snap7\common.py", line 89, in check_error
    raise RuntimeError(error)
RuntimeError: b' TCP : Unreachable peer'

2023-05-04 18:37:55,445 _plc_.client Подключение к контроллеру 192.168.0.10...
2023-05-04 18:37:55,762 snap7.common b' TCP : Unreachable peer'
2023-05-04 18:37:55,764 _plc_.client Не удалось подключиться к контроллеру: 192.168.0.10
Ошибка b' TCP : Unreachable peer' Traceback (most recent call last):
  File "D:\Work\DMU85\PLC_CV\python\plc.py", line 76, in run
    self.snap7client.connect(self.plc_ip, 0, 1)
  File "D:\Work\DMU85\PLC_CV\venv\lib\site-packages\snap7\client\__init__.py", line 24, in f
    check_error(code, context="client")
  File "D:\Work\DMU85\PLC_CV\venv\lib\site-packages\snap7\common.py", line 89, in check_error
    raise RuntimeError(error)
RuntimeError: b' TCP : Unreachable peer'

2023-05-04 18:38:55,940 _plc_.client Подключение к контроллеру 192.168.0.10...
2023-05-04 18:38:56,262 snap7.common b' TCP : Unreachable peer'
2023-05-04 18:38:56,263 _plc_.client Не удалось подключиться к контроллеру: 192.168.0.10
Ошибка b' TCP : Unreachable peer' Traceback (most recent call last):
  File "D:\Work\DMU85\PLC_CV\python\plc.py", line 76, in run
    self.snap7client.connect(self.plc_ip, 0, 1)
  File "D:\Work\DMU85\PLC_CV\venv\lib\site-packages\snap7\client\__init__.py", line 24, in f
    check_error(code, context="client")
  File "D:\Work\DMU85\PLC_CV\venv\lib\site-packages\snap7\common.py", line 89, in check_error
    raise RuntimeError(error)
RuntimeError: b' TCP : Unreachable peer'

2023-05-04 18:39:56,427 _plc_.client Подключение к контроллеру 192.168.0.10...
2023-05-04 18:39:56,756 snap7.common b' TCP : Unreachable peer'
2023-05-04 18:39:56,758 _plc_.client Не удалось подключиться к контроллеру: 192.168.0.10
Ошибка b' TCP : Unreachable peer' Traceback (most recent call last):
  File "D:\Work\DMU85\PLC_CV\python\plc.py", line 76, in run
    self.snap7client.connect(self.plc_ip, 0, 1)
  File "D:\Work\DMU85\PLC_CV\venv\lib\site-packages\snap7\client\__init__.py", line 24, in f
    check_error(code, context="client")
  File "D:\Work\DMU85\PLC_CV\venv\lib\site-packages\snap7\common.py", line 89, in check_error
    raise RuntimeError(error)
RuntimeError: b' TCP : Unreachable peer'

2023-05-04 18:40:56,943 _plc_.client Подключение к контроллеру 192.168.0.10...
2023-05-04 18:40:57,256 snap7.common b' TCP : Unreachable peer'
2023-05-04 18:40:57,257 _plc_.client Не удалось подключиться к контроллеру: 192.168.0.10
Ошибка b' TCP : Unreachable peer' Traceback (most recent call last):
  File "D:\Work\DMU85\PLC_CV\python\plc.py", line 76, in run
    self.snap7client.connect(self.plc_ip, 0, 1)
  File "D:\Work\DMU85\PLC_CV\venv\lib\site-packages\snap7\client\__init__.py", line 24, in f
    check_error(code, context="client")
  File "D:\Work\DMU85\PLC_CV\venv\lib\site-packages\snap7\common.py", line 89, in check_error
    raise RuntimeError(error)
RuntimeError: b' TCP : Unreachable peer'

2023-05-04 18:41:57,430 _plc_.client Подключение к контроллеру 192.168.0.10...
2023-05-04 18:41:57,755 snap7.common b' TCP : Unreachable peer'
2023-05-04 18:41:57,755 _plc_.client Не удалось подключиться к контроллеру: 192.168.0.10
Ошибка b' TCP : Unreachable peer' Traceback (most recent call last):
  File "D:\Work\DMU85\PLC_CV\python\plc.py", line 76, in run
    self.snap7client.connect(self.plc_ip, 0, 1)
  File "D:\Work\DMU85\PLC_CV\venv\lib\site-packages\snap7\client\__init__.py", line 24, in f
    check_error(code, context="client")
  File "D:\Work\DMU85\PLC_CV\venv\lib\site-packages\snap7\common.py", line 89, in check_error
    raise RuntimeError(error)
RuntimeError: b' TCP : Unreachable peer'

2023-05-04 18:42:57,924 _plc_.client Подключение к контроллеру 192.168.0.10...
2023-05-04 18:42:58,264 snap7.common b' TCP : Unreachable peer'
2023-05-04 18:42:58,266 _plc_.client Не удалось подключиться к контроллеру: 192.168.0.10
Ошибка b' TCP : Unreachable peer' Traceback (most recent call last):
  File "D:\Work\DMU85\PLC_CV\python\plc.py", line 76, in run
    self.snap7client.connect(self.plc_ip, 0, 1)
  File "D:\Work\DMU85\PLC_CV\venv\lib\site-packages\snap7\client\__init__.py", line 24, in f
    check_error(code, context="client")
  File "D:\Work\DMU85\PLC_CV\venv\lib\site-packages\snap7\common.py", line 89, in check_error
    raise RuntimeError(error)
RuntimeError: b' TCP : Unreachable peer'

2023-05-04 18:43:58,436 _plc_.client Подключение к контроллеру 192.168.0.10...
2023-05-04 18:43:58,754 snap7.common b' TCP : Unreachable peer'
2023-05-04 18:43:58,755 _plc_.client Не удалось подключиться к контроллеру: 192.168.0.10
Ошибка b' TCP : Unreachable peer' Traceback (most recent call last):
  File "D:\Work\DMU85\PLC_CV\python\plc.py", line 76, in run
    self.snap7client.connect(self.plc_ip, 0, 1)
  File "D:\Work\DMU85\PLC_CV\venv\lib\site-packages\snap7\client\__init__.py", line 24, in f
    check_error(code, context="client")
  File "D:\Work\DMU85\PLC_CV\venv\lib\site-packages\snap7\common.py", line 89, in check_error
    raise RuntimeError(error)
RuntimeError: b' TCP : Unreachable peer'

2023-05-04 18:44:58,927 _plc_.client Подключение к контроллеру 192.168.0.10...
2023-05-04 18:44:59,263 snap7.common b' TCP : Unreachable peer'
2023-05-04 18:44:59,265 _plc_.client Не удалось подключиться к контроллеру: 192.168.0.10
Ошибка b' TCP : Unreachable peer' Traceback (most recent call last):
  File "D:\Work\DMU85\PLC_CV\python\plc.py", line 76, in run
    self.snap7client.connect(self.plc_ip, 0, 1)
  File "D:\Work\DMU85\PLC_CV\venv\lib\site-packages\snap7\client\__init__.py", line 24, in f
    check_error(code, context="client")
  File "D:\Work\DMU85\PLC_CV\venv\lib\site-packages\snap7\common.py", line 89, in check_error
    raise RuntimeError(error)
RuntimeError: b' TCP : Unreachable peer'

2023-05-04 18:45:59,458 _plc_.client Подключение к контроллеру 192.168.0.10...
2023-05-04 18:45:59,759 snap7.common b' TCP : Unreachable peer'
2023-05-04 18:45:59,761 _plc_.client Не удалось подключиться к контроллеру: 192.168.0.10
Ошибка b' TCP : Unreachable peer' Traceback (most recent call last):
  File "D:\Work\DMU85\PLC_CV\python\plc.py", line 76, in run
    self.snap7client.connect(self.plc_ip, 0, 1)
  File "D:\Work\DMU85\PLC_CV\venv\lib\site-packages\snap7\client\__init__.py", line 24, in f
    check_error(code, context="client")
  File "D:\Work\DMU85\PLC_CV\venv\lib\site-packages\snap7\common.py", line 89, in check_error
    raise RuntimeError(error)
RuntimeError: b' TCP : Unreachable peer'

2023-05-04 18:46:59,947 _plc_.client Подключение к контроллеру 192.168.0.10...
2023-05-04 18:47:00,264 snap7.common b' TCP : Unreachable peer'
2023-05-04 18:47:00,265 _plc_.client Не удалось подключиться к контроллеру: 192.168.0.10
Ошибка b' TCP : Unreachable peer' Traceback (most recent call last):
  File "D:\Work\DMU85\PLC_CV\python\plc.py", line 76, in run
    self.snap7client.connect(self.plc_ip, 0, 1)
  File "D:\Work\DMU85\PLC_CV\venv\lib\site-packages\snap7\client\__init__.py", line 24, in f
    check_error(code, context="client")
  File "D:\Work\DMU85\PLC_CV\venv\lib\site-packages\snap7\common.py", line 89, in check_error
    raise RuntimeError(error)
RuntimeError: b' TCP : Unreachable peer'

2023-05-04 18:48:00,427 _plc_.client Подключение к контроллеру 192.168.0.10...
2023-05-04 18:48:00,760 snap7.common b' TCP : Unreachable peer'
2023-05-04 18:48:00,760 _plc_.client Не удалось подключиться к контроллеру: 192.168.0.10
Ошибка b' TCP : Unreachable peer' Traceback (most recent call last):
  File "D:\Work\DMU85\PLC_CV\python\plc.py", line 76, in run
    self.snap7client.connect(self.plc_ip, 0, 1)
  File "D:\Work\DMU85\PLC_CV\venv\lib\site-packages\snap7\client\__init__.py", line 24, in f
    check_error(code, context="client")
  File "D:\Work\DMU85\PLC_CV\venv\lib\site-packages\snap7\common.py", line 89, in check_error
    raise RuntimeError(error)
RuntimeError: b' TCP : Unreachable peer'

2023-05-04 18:49:00,929 _plc_.client Подключение к контроллеру 192.168.0.10...
2023-05-04 18:49:01,263 snap7.common b' TCP : Unreachable peer'
2023-05-04 18:49:01,263 _plc_.client Не удалось подключиться к контроллеру: 192.168.0.10
Ошибка b' TCP : Unreachable peer' Traceback (most recent call last):
  File "D:\Work\DMU85\PLC_CV\python\plc.py", line 76, in run
    self.snap7client.connect(self.plc_ip, 0, 1)
  File "D:\Work\DMU85\PLC_CV\venv\lib\site-packages\snap7\client\__init__.py", line 24, in f
    check_error(code, context="client")
  File "D:\Work\DMU85\PLC_CV\venv\lib\site-packages\snap7\common.py", line 89, in check_error
    raise RuntimeError(error)
RuntimeError: b' TCP : Unreachable peer'

2023-05-04 18:50:01,440 _plc_.client Подключение к контроллеру 192.168.0.10...
2023-05-04 18:50:01,763 snap7.common b' TCP : Unreachable peer'
2023-05-04 18:50:01,764 _plc_.client Не удалось подключиться к контроллеру: 192.168.0.10
Ошибка b' TCP : Unreachable peer' Traceback (most recent call last):
  File "D:\Work\DMU85\PLC_CV\python\plc.py", line 76, in run
    self.snap7client.connect(self.plc_ip, 0, 1)
  File "D:\Work\DMU85\PLC_CV\venv\lib\site-packages\snap7\client\__init__.py", line 24, in f
    check_error(code, context="client")
  File "D:\Work\DMU85\PLC_CV\venv\lib\site-packages\snap7\common.py", line 89, in check_error
    raise RuntimeError(error)
RuntimeError: b' TCP : Unreachable peer'

2023-05-04 18:51:01,942 _plc_.client Подключение к контроллеру 192.168.0.10...
2023-05-04 18:51:02,261 snap7.common b' TCP : Unreachable peer'
2023-05-04 18:51:02,262 _plc_.client Не удалось подключиться к контроллеру: 192.168.0.10
Ошибка b' TCP : Unreachable peer' Traceback (most recent call last):
  File "D:\Work\DMU85\PLC_CV\python\plc.py", line 76, in run
    self.snap7client.connect(self.plc_ip, 0, 1)
  File "D:\Work\DMU85\PLC_CV\venv\lib\site-packages\snap7\client\__init__.py", line 24, in f
    check_error(code, context="client")
  File "D:\Work\DMU85\PLC_CV\venv\lib\site-packages\snap7\common.py", line 89, in check_error
    raise RuntimeError(error)
RuntimeError: b' TCP : Unreachable peer'

2023-05-04 18:52:02,436 _plc_.client Подключение к контроллеру 192.168.0.10...
2023-05-04 18:52:02,766 snap7.common b' TCP : Unreachable peer'
2023-05-04 18:52:02,767 _plc_.client Не удалось подключиться к контроллеру: 192.168.0.10
Ошибка b' TCP : Unreachable peer' Traceback (most recent call last):
  File "D:\Work\DMU85\PLC_CV\python\plc.py", line 76, in run
    self.snap7client.connect(self.plc_ip, 0, 1)
  File "D:\Work\DMU85\PLC_CV\venv\lib\site-packages\snap7\client\__init__.py", line 24, in f
    check_error(code, context="client")
  File "D:\Work\DMU85\PLC_CV\venv\lib\site-packages\snap7\common.py", line 89, in check_error
    raise RuntimeError(error)
RuntimeError: b' TCP : Unreachable peer'

2023-05-04 18:53:02,953 _plc_.client Подключение к контроллеру 192.168.0.10...
2023-05-04 18:53:03,253 snap7.common b' TCP : Unreachable peer'
2023-05-04 18:53:03,254 _plc_.client Не удалось подключиться к контроллеру: 192.168.0.10
Ошибка b' TCP : Unreachable peer' Traceback (most recent call last):
  File "D:\Work\DMU85\PLC_CV\python\plc.py", line 76, in run
    self.snap7client.connect(self.plc_ip, 0, 1)
  File "D:\Work\DMU85\PLC_CV\venv\lib\site-packages\snap7\client\__init__.py", line 24, in f
    check_error(code, context="client")
  File "D:\Work\DMU85\PLC_CV\venv\lib\site-packages\snap7\common.py", line 89, in check_error
    raise RuntimeError(error)
RuntimeError: b' TCP : Unreachable peer'

2023-05-04 18:54:03,438 _plc_.client Подключение к контроллеру 192.168.0.10...
2023-05-04 18:54:03,784 snap7.common b' TCP : Unreachable peer'
2023-05-04 18:54:03,785 _plc_.client Не удалось подключиться к контроллеру: 192.168.0.10
Ошибка b' TCP : Unreachable peer' Traceback (most recent call last):
  File "D:\Work\DMU85\PLC_CV\python\plc.py", line 76, in run
    self.snap7client.connect(self.plc_ip, 0, 1)
  File "D:\Work\DMU85\PLC_CV\venv\lib\site-packages\snap7\client\__init__.py", line 24, in f
    check_error(code, context="client")
  File "D:\Work\DMU85\PLC_CV\venv\lib\site-packages\snap7\common.py", line 89, in check_error
    raise RuntimeError(error)
RuntimeError: b' TCP : Unreachable peer'

2023-05-04 18:55:03,971 _plc_.client Подключение к контроллеру 192.168.0.10...
2023-05-04 18:55:04,250 snap7.common b' TCP : Unreachable peer'
2023-05-04 18:55:04,253 _plc_.client Не удалось подключиться к контроллеру: 192.168.0.10
Ошибка b' TCP : Unreachable peer' Traceback (most recent call last):
  File "D:\Work\DMU85\PLC_CV\python\plc.py", line 76, in run
    self.snap7client.connect(self.plc_ip, 0, 1)
  File "D:\Work\DMU85\PLC_CV\venv\lib\site-packages\snap7\client\__init__.py", line 24, in f
    check_error(code, context="client")
  File "D:\Work\DMU85\PLC_CV\venv\lib\site-packages\snap7\common.py", line 89, in check_error
    raise RuntimeError(error)
RuntimeError: b' TCP : Unreachable peer'

2023-05-04 18:56:04,434 _plc_.client Подключение к контроллеру 192.168.0.10...
2023-05-04 18:56:04,761 snap7.common b' TCP : Unreachable peer'
2023-05-04 18:56:04,761 _plc_.client Не удалось подключиться к контроллеру: 192.168.0.10
Ошибка b' TCP : Unreachable peer' Traceback (most recent call last):
  File "D:\Work\DMU85\PLC_CV\python\plc.py", line 76, in run
    self.snap7client.connect(self.plc_ip, 0, 1)
  File "D:\Work\DMU85\PLC_CV\venv\lib\site-packages\snap7\client\__init__.py", line 24, in f
    check_error(code, context="client")
  File "D:\Work\DMU85\PLC_CV\venv\lib\site-packages\snap7\common.py", line 89, in check_error
    raise RuntimeError(error)
RuntimeError: b' TCP : Unreachable peer'

2023-05-04 18:57:04,939 _plc_.client Подключение к контроллеру 192.168.0.10...
2023-05-04 18:57:05,259 snap7.common b' TCP : Unreachable peer'
2023-05-04 18:57:05,260 _plc_.client Не удалось подключиться к контроллеру: 192.168.0.10
Ошибка b' TCP : Unreachable peer' Traceback (most recent call last):
  File "D:\Work\DMU85\PLC_CV\python\plc.py", line 76, in run
    self.snap7client.connect(self.plc_ip, 0, 1)
  File "D:\Work\DMU85\PLC_CV\venv\lib\site-packages\snap7\client\__init__.py", line 24, in f
    check_error(code, context="client")
  File "D:\Work\DMU85\PLC_CV\venv\lib\site-packages\snap7\common.py", line 89, in check_error
    raise RuntimeError(error)
RuntimeError: b' TCP : Unreachable peer'

2023-05-04 18:58:05,445 _plc_.client Подключение к контроллеру 192.168.0.10...
2023-05-04 18:58:05,777 snap7.common b' TCP : Unreachable peer'
2023-05-04 18:58:05,777 _plc_.client Не удалось подключиться к контроллеру: 192.168.0.10
Ошибка b' TCP : Unreachable peer' Traceback (most recent call last):
  File "D:\Work\DMU85\PLC_CV\python\plc.py", line 76, in run
    self.snap7client.connect(self.plc_ip, 0, 1)
  File "D:\Work\DMU85\PLC_CV\venv\lib\site-packages\snap7\client\__init__.py", line 24, in f
    check_error(code, context="client")
  File "D:\Work\DMU85\PLC_CV\venv\lib\site-packages\snap7\common.py", line 89, in check_error
    raise RuntimeError(error)
RuntimeError: b' TCP : Unreachable peer'

2023-05-04 18:59:05,947 _plc_.client Подключение к контроллеру 192.168.0.10...
2023-05-04 18:59:06,251 snap7.common b' TCP : Unreachable peer'
2023-05-04 18:59:06,252 _plc_.client Не удалось подключиться к контроллеру: 192.168.0.10
Ошибка b' TCP : Unreachable peer' Traceback (most recent call last):
  File "D:\Work\DMU85\PLC_CV\python\plc.py", line 76, in run
    self.snap7client.connect(self.plc_ip, 0, 1)
  File "D:\Work\DMU85\PLC_CV\venv\lib\site-packages\snap7\client\__init__.py", line 24, in f
    check_error(code, context="client")
  File "D:\Work\DMU85\PLC_CV\venv\lib\site-packages\snap7\common.py", line 89, in check_error
    raise RuntimeError(error)
RuntimeError: b' TCP : Unreachable peer'

2023-05-04 19:00:06,441 _plc_.client Подключение к контроллеру 192.168.0.10...
2023-05-04 19:00:06,762 snap7.common b' TCP : Unreachable peer'
2023-05-04 19:00:06,762 _plc_.client Не удалось подключиться к контроллеру: 192.168.0.10
Ошибка b' TCP : Unreachable peer' Traceback (most recent call last):
  File "D:\Work\DMU85\PLC_CV\python\plc.py", line 76, in run
    self.snap7client.connect(self.plc_ip, 0, 1)
  File "D:\Work\DMU85\PLC_CV\venv\lib\site-packages\snap7\client\__init__.py", line 24, in f
    check_error(code, context="client")
  File "D:\Work\DMU85\PLC_CV\venv\lib\site-packages\snap7\common.py", line 89, in check_error
    raise RuntimeError(error)
RuntimeError: b' TCP : Unreachable peer'

2023-05-04 19:01:06,946 _plc_.client Подключение к контроллеру 192.168.0.10...
2023-05-04 19:01:07,251 snap7.common b' TCP : Unreachable peer'
2023-05-04 19:01:07,253 _plc_.client Не удалось подключиться к контроллеру: 192.168.0.10
Ошибка b' TCP : Unreachable peer' Traceback (most recent call last):
  File "D:\Work\DMU85\PLC_CV\python\plc.py", line 76, in run
    self.snap7client.connect(self.plc_ip, 0, 1)
  File "D:\Work\DMU85\PLC_CV\venv\lib\site-packages\snap7\client\__init__.py", line 24, in f
    check_error(code, context="client")
  File "D:\Work\DMU85\PLC_CV\venv\lib\site-packages\snap7\common.py", line 89, in check_error
    raise RuntimeError(error)
RuntimeError: b' TCP : Unreachable peer'

2023-05-04 19:02:07,424 _plc_.client Подключение к контроллеру 192.168.0.10...
2023-05-04 19:02:07,755 snap7.common b' TCP : Unreachable peer'
2023-05-04 19:02:07,756 _plc_.client Не удалось подключиться к контроллеру: 192.168.0.10
Ошибка b' TCP : Unreachable peer' Traceback (most recent call last):
  File "D:\Work\DMU85\PLC_CV\python\plc.py", line 76, in run
    self.snap7client.connect(self.plc_ip, 0, 1)
  File "D:\Work\DMU85\PLC_CV\venv\lib\site-packages\snap7\client\__init__.py", line 24, in f
    check_error(code, context="client")
  File "D:\Work\DMU85\PLC_CV\venv\lib\site-packages\snap7\common.py", line 89, in check_error
    raise RuntimeError(error)
RuntimeError: b' TCP : Unreachable peer'

2023-05-04 19:03:07,925 _plc_.client Подключение к контроллеру 192.168.0.10...
2023-05-04 19:03:08,266 snap7.common b' TCP : Unreachable peer'
2023-05-04 19:03:08,267 _plc_.client Не удалось подключиться к контроллеру: 192.168.0.10
Ошибка b' TCP : Unreachable peer' Traceback (most recent call last):
  File "D:\Work\DMU85\PLC_CV\python\plc.py", line 76, in run
    self.snap7client.connect(self.plc_ip, 0, 1)
  File "D:\Work\DMU85\PLC_CV\venv\lib\site-packages\snap7\client\__init__.py", line 24, in f
    check_error(code, context="client")
  File "D:\Work\DMU85\PLC_CV\venv\lib\site-packages\snap7\common.py", line 89, in check_error
    raise RuntimeError(error)
RuntimeError: b' TCP : Unreachable peer'

2023-05-04 19:04:08,450 _plc_.client Подключение к контроллеру 192.168.0.10...
2023-05-04 19:04:08,754 snap7.common b' TCP : Unreachable peer'
2023-05-04 19:04:08,755 _plc_.client Не удалось подключиться к контроллеру: 192.168.0.10
Ошибка b' TCP : Unreachable peer' Traceback (most recent call last):
  File "D:\Work\DMU85\PLC_CV\python\plc.py", line 76, in run
    self.snap7client.connect(self.plc_ip, 0, 1)
  File "D:\Work\DMU85\PLC_CV\venv\lib\site-packages\snap7\client\__init__.py", line 24, in f
    check_error(code, context="client")
  File "D:\Work\DMU85\PLC_CV\venv\lib\site-packages\snap7\common.py", line 89, in check_error
    raise RuntimeError(error)
RuntimeError: b' TCP : Unreachable peer'

2023-05-04 19:05:08,927 _plc_.client Подключение к контроллеру 192.168.0.10...
2023-05-04 19:05:09,253 snap7.common b' TCP : Unreachable peer'
2023-05-04 19:05:09,254 _plc_.client Не удалось подключиться к контроллеру: 192.168.0.10
Ошибка b' TCP : Unreachable peer' Traceback (most recent call last):
  File "D:\Work\DMU85\PLC_CV\python\plc.py", line 76, in run
    self.snap7client.connect(self.plc_ip, 0, 1)
  File "D:\Work\DMU85\PLC_CV\venv\lib\site-packages\snap7\client\__init__.py", line 24, in f
    check_error(code, context="client")
  File "D:\Work\DMU85\PLC_CV\venv\lib\site-packages\snap7\common.py", line 89, in check_error
    raise RuntimeError(error)
RuntimeError: b' TCP : Unreachable peer'

2023-05-04 19:06:09,431 _plc_.client Подключение к контроллеру 192.168.0.10...
2023-05-04 19:06:09,764 snap7.common b' TCP : Unreachable peer'
2023-05-04 19:06:09,765 _plc_.client Не удалось подключиться к контроллеру: 192.168.0.10
Ошибка b' TCP : Unreachable peer' Traceback (most recent call last):
  File "D:\Work\DMU85\PLC_CV\python\plc.py", line 76, in run
    self.snap7client.connect(self.plc_ip, 0, 1)
  File "D:\Work\DMU85\PLC_CV\venv\lib\site-packages\snap7\client\__init__.py", line 24, in f
    check_error(code, context="client")
  File "D:\Work\DMU85\PLC_CV\venv\lib\site-packages\snap7\common.py", line 89, in check_error
    raise RuntimeError(error)
RuntimeError: b' TCP : Unreachable peer'

2023-05-04 19:07:09,941 _plc_.client Подключение к контроллеру 192.168.0.10...
2023-05-04 19:07:10,263 snap7.common b' TCP : Unreachable peer'
2023-05-04 19:07:10,264 _plc_.client Не удалось подключиться к контроллеру: 192.168.0.10
Ошибка b' TCP : Unreachable peer' Traceback (most recent call last):
  File "D:\Work\DMU85\PLC_CV\python\plc.py", line 76, in run
    self.snap7client.connect(self.plc_ip, 0, 1)
  File "D:\Work\DMU85\PLC_CV\venv\lib\site-packages\snap7\client\__init__.py", line 24, in f
    check_error(code, context="client")
  File "D:\Work\DMU85\PLC_CV\venv\lib\site-packages\snap7\common.py", line 89, in check_error
    raise RuntimeError(error)
RuntimeError: b' TCP : Unreachable peer'

2023-05-04 19:08:10,439 _plc_.client Подключение к контроллеру 192.168.0.10...
2023-05-04 19:08:10,760 snap7.common b' TCP : Unreachable peer'
2023-05-04 19:08:10,761 _plc_.client Не удалось подключиться к контроллеру: 192.168.0.10
Ошибка b' TCP : Unreachable peer' Traceback (most recent call last):
  File "D:\Work\DMU85\PLC_CV\python\plc.py", line 76, in run
    self.snap7client.connect(self.plc_ip, 0, 1)
  File "D:\Work\DMU85\PLC_CV\venv\lib\site-packages\snap7\client\__init__.py", line 24, in f
    check_error(code, context="client")
  File "D:\Work\DMU85\PLC_CV\venv\lib\site-packages\snap7\common.py", line 89, in check_error
    raise RuntimeError(error)
RuntimeError: b' TCP : Unreachable peer'

2023-05-04 19:09:10,935 _plc_.client Подключение к контроллеру 192.168.0.10...
2023-05-04 19:09:11,264 snap7.common b' TCP : Unreachable peer'
2023-05-04 19:09:11,265 _plc_.client Не удалось подключиться к контроллеру: 192.168.0.10
Ошибка b' TCP : Unreachable peer' Traceback (most recent call last):
  File "D:\Work\DMU85\PLC_CV\python\plc.py", line 76, in run
    self.snap7client.connect(self.plc_ip, 0, 1)
  File "D:\Work\DMU85\PLC_CV\venv\lib\site-packages\snap7\client\__init__.py", line 24, in f
    check_error(code, context="client")
  File "D:\Work\DMU85\PLC_CV\venv\lib\site-packages\snap7\common.py", line 89, in check_error
    raise RuntimeError(error)
RuntimeError: b' TCP : Unreachable peer'

2023-05-04 19:10:11,424 _plc_.client Подключение к контроллеру 192.168.0.10...
2023-05-04 19:10:11,759 snap7.common b' TCP : Unreachable peer'
2023-05-04 19:10:11,760 _plc_.client Не удалось подключиться к контроллеру: 192.168.0.10
Ошибка b' TCP : Unreachable peer' Traceback (most recent call last):
  File "D:\Work\DMU85\PLC_CV\python\plc.py", line 76, in run
    self.snap7client.connect(self.plc_ip, 0, 1)
  File "D:\Work\DMU85\PLC_CV\venv\lib\site-packages\snap7\client\__init__.py", line 24, in f
    check_error(code, context="client")
  File "D:\Work\DMU85\PLC_CV\venv\lib\site-packages\snap7\common.py", line 89, in check_error
    raise RuntimeError(error)
RuntimeError: b' TCP : Unreachable peer'

2023-05-04 19:11:11,931 _plc_.client Подключение к контроллеру 192.168.0.10...
2023-05-04 19:11:12,264 snap7.common b' TCP : Unreachable peer'
2023-05-04 19:11:12,265 _plc_.client Не удалось подключиться к контроллеру: 192.168.0.10
Ошибка b' TCP : Unreachable peer' Traceback (most recent call last):
  File "D:\Work\DMU85\PLC_CV\python\plc.py", line 76, in run
    self.snap7client.connect(self.plc_ip, 0, 1)
  File "D:\Work\DMU85\PLC_CV\venv\lib\site-packages\snap7\client\__init__.py", line 24, in f
    check_error(code, context="client")
  File "D:\Work\DMU85\PLC_CV\venv\lib\site-packages\snap7\common.py", line 89, in check_error
    raise RuntimeError(error)
RuntimeError: b' TCP : Unreachable peer'

2023-05-04 19:12:12,447 _plc_.client Подключение к контроллеру 192.168.0.10...
2023-05-04 19:12:12,759 snap7.common b' TCP : Unreachable peer'
2023-05-04 19:12:12,759 _plc_.client Не удалось подключиться к контроллеру: 192.168.0.10
Ошибка b' TCP : Unreachable peer' Traceback (most recent call last):
  File "D:\Work\DMU85\PLC_CV\python\plc.py", line 76, in run
    self.snap7client.connect(self.plc_ip, 0, 1)
  File "D:\Work\DMU85\PLC_CV\venv\lib\site-packages\snap7\client\__init__.py", line 24, in f
    check_error(code, context="client")
  File "D:\Work\DMU85\PLC_CV\venv\lib\site-packages\snap7\common.py", line 89, in check_error
    raise RuntimeError(error)
RuntimeError: b' TCP : Unreachable peer'

2023-05-04 19:13:12,953 _plc_.client Подключение к контроллеру 192.168.0.10...
2023-05-04 19:13:13,255 snap7.common b' TCP : Unreachable peer'
2023-05-04 19:13:13,256 _plc_.client Не удалось подключиться к контроллеру: 192.168.0.10
Ошибка b' TCP : Unreachable peer' Traceback (most recent call last):
  File "D:\Work\DMU85\PLC_CV\python\plc.py", line 76, in run
    self.snap7client.connect(self.plc_ip, 0, 1)
  File "D:\Work\DMU85\PLC_CV\venv\lib\site-packages\snap7\client\__init__.py", line 24, in f
    check_error(code, context="client")
  File "D:\Work\DMU85\PLC_CV\venv\lib\site-packages\snap7\common.py", line 89, in check_error
    raise RuntimeError(error)
RuntimeError: b' TCP : Unreachable peer'

2023-05-04 19:14:13,420 _plc_.client Подключение к контроллеру 192.168.0.10...
2023-05-04 19:14:13,759 snap7.common b' TCP : Unreachable peer'
2023-05-04 19:14:13,759 _plc_.client Не удалось подключиться к контроллеру: 192.168.0.10
Ошибка b' TCP : Unreachable peer' Traceback (most recent call last):
  File "D:\Work\DMU85\PLC_CV\python\plc.py", line 76, in run
    self.snap7client.connect(self.plc_ip, 0, 1)
  File "D:\Work\DMU85\PLC_CV\venv\lib\site-packages\snap7\client\__init__.py", line 24, in f
    check_error(code, context="client")
  File "D:\Work\DMU85\PLC_CV\venv\lib\site-packages\snap7\common.py", line 89, in check_error
    raise RuntimeError(error)
RuntimeError: b' TCP : Unreachable peer'

2023-05-04 19:15:13,925 _plc_.client Подключение к контроллеру 192.168.0.10...
2023-05-04 19:15:14,258 snap7.common b' TCP : Unreachable peer'
2023-05-04 19:15:14,259 _plc_.client Не удалось подключиться к контроллеру: 192.168.0.10
Ошибка b' TCP : Unreachable peer' Traceback (most recent call last):
  File "D:\Work\DMU85\PLC_CV\python\plc.py", line 76, in run
    self.snap7client.connect(self.plc_ip, 0, 1)
  File "D:\Work\DMU85\PLC_CV\venv\lib\site-packages\snap7\client\__init__.py", line 24, in f
    check_error(code, context="client")
  File "D:\Work\DMU85\PLC_CV\venv\lib\site-packages\snap7\common.py", line 89, in check_error
    raise RuntimeError(error)
RuntimeError: b' TCP : Unreachable peer'

2023-05-04 19:16:14,431 _plc_.client Подключение к контроллеру 192.168.0.10...
2023-05-04 19:16:14,764 snap7.common b' TCP : Unreachable peer'
2023-05-04 19:16:14,765 _plc_.client Не удалось подключиться к контроллеру: 192.168.0.10
Ошибка b' TCP : Unreachable peer' Traceback (most recent call last):
  File "D:\Work\DMU85\PLC_CV\python\plc.py", line 76, in run
    self.snap7client.connect(self.plc_ip, 0, 1)
  File "D:\Work\DMU85\PLC_CV\venv\lib\site-packages\snap7\client\__init__.py", line 24, in f
    check_error(code, context="client")
  File "D:\Work\DMU85\PLC_CV\venv\lib\site-packages\snap7\common.py", line 89, in check_error
    raise RuntimeError(error)
RuntimeError: b' TCP : Unreachable peer'

2023-05-04 19:17:14,941 _plc_.client Подключение к контроллеру 192.168.0.10...
2023-05-04 19:17:15,262 snap7.common b' TCP : Unreachable peer'
2023-05-04 19:17:15,263 _plc_.client Не удалось подключиться к контроллеру: 192.168.0.10
Ошибка b' TCP : Unreachable peer' Traceback (most recent call last):
  File "D:\Work\DMU85\PLC_CV\python\plc.py", line 76, in run
    self.snap7client.connect(self.plc_ip, 0, 1)
  File "D:\Work\DMU85\PLC_CV\venv\lib\site-packages\snap7\client\__init__.py", line 24, in f
    check_error(code, context="client")
  File "D:\Work\DMU85\PLC_CV\venv\lib\site-packages\snap7\common.py", line 89, in check_error
    raise RuntimeError(error)
RuntimeError: b' TCP : Unreachable peer'

2023-05-04 19:18:15,441 _plc_.client Подключение к контроллеру 192.168.0.10...
2023-05-04 19:18:15,762 snap7.common b' TCP : Unreachable peer'
2023-05-04 19:18:15,763 _plc_.client Не удалось подключиться к контроллеру: 192.168.0.10
Ошибка b' TCP : Unreachable peer' Traceback (most recent call last):
  File "D:\Work\DMU85\PLC_CV\python\plc.py", line 76, in run
    self.snap7client.connect(self.plc_ip, 0, 1)
  File "D:\Work\DMU85\PLC_CV\venv\lib\site-packages\snap7\client\__init__.py", line 24, in f
    check_error(code, context="client")
  File "D:\Work\DMU85\PLC_CV\venv\lib\site-packages\snap7\common.py", line 89, in check_error
    raise RuntimeError(error)
RuntimeError: b' TCP : Unreachable peer'

2023-05-04 19:19:15,939 _plc_.client Подключение к контроллеру 192.168.0.10...
2023-05-04 19:19:16,263 snap7.common b' TCP : Unreachable peer'
2023-05-04 19:19:16,263 _plc_.client Не удалось подключиться к контроллеру: 192.168.0.10
Ошибка b' TCP : Unreachable peer' Traceback (most recent call last):
  File "D:\Work\DMU85\PLC_CV\python\plc.py", line 76, in run
    self.snap7client.connect(self.plc_ip, 0, 1)
  File "D:\Work\DMU85\PLC_CV\venv\lib\site-packages\snap7\client\__init__.py", line 24, in f
    check_error(code, context="client")
  File "D:\Work\DMU85\PLC_CV\venv\lib\site-packages\snap7\common.py", line 89, in check_error
    raise RuntimeError(error)
RuntimeError: b' TCP : Unreachable peer'

2023-05-04 19:20:16,426 _plc_.client Подключение к контроллеру 192.168.0.10...
2023-05-04 19:20:16,759 snap7.common b' TCP : Unreachable peer'
2023-05-04 19:20:16,760 _plc_.client Не удалось подключиться к контроллеру: 192.168.0.10
Ошибка b' TCP : Unreachable peer' Traceback (most recent call last):
  File "D:\Work\DMU85\PLC_CV\python\plc.py", line 76, in run
    self.snap7client.connect(self.plc_ip, 0, 1)
  File "D:\Work\DMU85\PLC_CV\venv\lib\site-packages\snap7\client\__init__.py", line 24, in f
    check_error(code, context="client")
  File "D:\Work\DMU85\PLC_CV\venv\lib\site-packages\snap7\common.py", line 89, in check_error
    raise RuntimeError(error)
RuntimeError: b' TCP : Unreachable peer'

2023-05-04 19:21:16,941 _plc_.client Подключение к контроллеру 192.168.0.10...
2023-05-04 19:21:17,265 snap7.common b' TCP : Unreachable peer'
2023-05-04 19:21:17,266 _plc_.client Не удалось подключиться к контроллеру: 192.168.0.10
Ошибка b' TCP : Unreachable peer' Traceback (most recent call last):
  File "D:\Work\DMU85\PLC_CV\python\plc.py", line 76, in run
    self.snap7client.connect(self.plc_ip, 0, 1)
  File "D:\Work\DMU85\PLC_CV\venv\lib\site-packages\snap7\client\__init__.py", line 24, in f
    check_error(code, context="client")
  File "D:\Work\DMU85\PLC_CV\venv\lib\site-packages\snap7\common.py", line 89, in check_error
    raise RuntimeError(error)
RuntimeError: b' TCP : Unreachable peer'

2023-05-04 19:22:17,434 _plc_.client Подключение к контроллеру 192.168.0.10...
2023-05-04 19:22:17,760 snap7.common b' TCP : Unreachable peer'
2023-05-04 19:22:17,761 _plc_.client Не удалось подключиться к контроллеру: 192.168.0.10
Ошибка b' TCP : Unreachable peer' Traceback (most recent call last):
  File "D:\Work\DMU85\PLC_CV\python\plc.py", line 76, in run
    self.snap7client.connect(self.plc_ip, 0, 1)
  File "D:\Work\DMU85\PLC_CV\venv\lib\site-packages\snap7\client\__init__.py", line 24, in f
    check_error(code, context="client")
  File "D:\Work\DMU85\PLC_CV\venv\lib\site-packages\snap7\common.py", line 89, in check_error
    raise RuntimeError(error)
RuntimeError: b' TCP : Unreachable peer'

2023-05-04 19:23:17,929 _plc_.client Подключение к контроллеру 192.168.0.10...
2023-05-04 19:23:18,261 snap7.common b' TCP : Unreachable peer'
2023-05-04 19:23:18,262 _plc_.client Не удалось подключиться к контроллеру: 192.168.0.10
Ошибка b' TCP : Unreachable peer' Traceback (most recent call last):
  File "D:\Work\DMU85\PLC_CV\python\plc.py", line 76, in run
    self.snap7client.connect(self.plc_ip, 0, 1)
  File "D:\Work\DMU85\PLC_CV\venv\lib\site-packages\snap7\client\__init__.py", line 24, in f
    check_error(code, context="client")
  File "D:\Work\DMU85\PLC_CV\venv\lib\site-packages\snap7\common.py", line 89, in check_error
    raise RuntimeError(error)
RuntimeError: b' TCP : Unreachable peer'

2023-05-04 19:24:18,446 _plc_.client Подключение к контроллеру 192.168.0.10...
2023-05-04 19:24:18,754 snap7.common b' TCP : Unreachable peer'
2023-05-04 19:24:18,755 _plc_.client Не удалось подключиться к контроллеру: 192.168.0.10
Ошибка b' TCP : Unreachable peer' Traceback (most recent call last):
  File "D:\Work\DMU85\PLC_CV\python\plc.py", line 76, in run
    self.snap7client.connect(self.plc_ip, 0, 1)
  File "D:\Work\DMU85\PLC_CV\venv\lib\site-packages\snap7\client\__init__.py", line 24, in f
    check_error(code, context="client")
  File "D:\Work\DMU85\PLC_CV\venv\lib\site-packages\snap7\common.py", line 89, in check_error
    raise RuntimeError(error)
RuntimeError: b' TCP : Unreachable peer'

2023-05-04 19:25:18,921 _plc_.client Подключение к контроллеру 192.168.0.10...
2023-05-04 19:25:19,253 snap7.common b' TCP : Unreachable peer'
2023-05-04 19:25:19,254 _plc_.client Не удалось подключиться к контроллеру: 192.168.0.10
Ошибка b' TCP : Unreachable peer' Traceback (most recent call last):
  File "D:\Work\DMU85\PLC_CV\python\plc.py", line 76, in run
    self.snap7client.connect(self.plc_ip, 0, 1)
  File "D:\Work\DMU85\PLC_CV\venv\lib\site-packages\snap7\client\__init__.py", line 24, in f
    check_error(code, context="client")
  File "D:\Work\DMU85\PLC_CV\venv\lib\site-packages\snap7\common.py", line 89, in check_error
    raise RuntimeError(error)
RuntimeError: b' TCP : Unreachable peer'

2023-05-04 19:26:19,430 _plc_.client Подключение к контроллеру 192.168.0.10...
2023-05-04 19:26:19,750 snap7.common b' TCP : Unreachable peer'
2023-05-04 19:26:19,751 _plc_.client Не удалось подключиться к контроллеру: 192.168.0.10
Ошибка b' TCP : Unreachable peer' Traceback (most recent call last):
  File "D:\Work\DMU85\PLC_CV\python\plc.py", line 76, in run
    self.snap7client.connect(self.plc_ip, 0, 1)
  File "D:\Work\DMU85\PLC_CV\venv\lib\site-packages\snap7\client\__init__.py", line 24, in f
    check_error(code, context="client")
  File "D:\Work\DMU85\PLC_CV\venv\lib\site-packages\snap7\common.py", line 89, in check_error
    raise RuntimeError(error)
RuntimeError: b' TCP : Unreachable peer'

2023-05-04 19:27:19,922 _plc_.client Подключение к контроллеру 192.168.0.10...
2023-05-04 19:27:20,258 snap7.common b' TCP : Unreachable peer'
2023-05-04 19:27:20,259 _plc_.client Не удалось подключиться к контроллеру: 192.168.0.10
Ошибка b' TCP : Unreachable peer' Traceback (most recent call last):
  File "D:\Work\DMU85\PLC_CV\python\plc.py", line 76, in run
    self.snap7client.connect(self.plc_ip, 0, 1)
  File "D:\Work\DMU85\PLC_CV\venv\lib\site-packages\snap7\client\__init__.py", line 24, in f
    check_error(code, context="client")
  File "D:\Work\DMU85\PLC_CV\venv\lib\site-packages\snap7\common.py", line 89, in check_error
    raise RuntimeError(error)
RuntimeError: b' TCP : Unreachable peer'

2023-05-04 19:28:20,427 _plc_.client Подключение к контроллеру 192.168.0.10...
2023-05-04 19:28:20,760 snap7.common b' TCP : Unreachable peer'
2023-05-04 19:28:20,762 _plc_.client Не удалось подключиться к контроллеру: 192.168.0.10
Ошибка b' TCP : Unreachable peer' Traceback (most recent call last):
  File "D:\Work\DMU85\PLC_CV\python\plc.py", line 76, in run
    self.snap7client.connect(self.plc_ip, 0, 1)
  File "D:\Work\DMU85\PLC_CV\venv\lib\site-packages\snap7\client\__init__.py", line 24, in f
    check_error(code, context="client")
  File "D:\Work\DMU85\PLC_CV\venv\lib\site-packages\snap7\common.py", line 89, in check_error
    raise RuntimeError(error)
RuntimeError: b' TCP : Unreachable peer'

2023-05-04 19:29:20,931 _plc_.client Подключение к контроллеру 192.168.0.10...
2023-05-04 19:29:21,252 snap7.common b' TCP : Unreachable peer'
2023-05-04 19:29:21,254 _plc_.client Не удалось подключиться к контроллеру: 192.168.0.10
Ошибка b' TCP : Unreachable peer' Traceback (most recent call last):
  File "D:\Work\DMU85\PLC_CV\python\plc.py", line 76, in run
    self.snap7client.connect(self.plc_ip, 0, 1)
  File "D:\Work\DMU85\PLC_CV\venv\lib\site-packages\snap7\client\__init__.py", line 24, in f
    check_error(code, context="client")
  File "D:\Work\DMU85\PLC_CV\venv\lib\site-packages\snap7\common.py", line 89, in check_error
    raise RuntimeError(error)
RuntimeError: b' TCP : Unreachable peer'

2023-05-04 19:30:21,428 _plc_.client Подключение к контроллеру 192.168.0.10...
2023-05-04 19:30:21,754 snap7.common b' TCP : Unreachable peer'
2023-05-04 19:30:21,754 _plc_.client Не удалось подключиться к контроллеру: 192.168.0.10
Ошибка b' TCP : Unreachable peer' Traceback (most recent call last):
  File "D:\Work\DMU85\PLC_CV\python\plc.py", line 76, in run
    self.snap7client.connect(self.plc_ip, 0, 1)
  File "D:\Work\DMU85\PLC_CV\venv\lib\site-packages\snap7\client\__init__.py", line 24, in f
    check_error(code, context="client")
  File "D:\Work\DMU85\PLC_CV\venv\lib\site-packages\snap7\common.py", line 89, in check_error
    raise RuntimeError(error)
RuntimeError: b' TCP : Unreachable peer'

2023-05-04 19:31:21,921 _plc_.client Подключение к контроллеру 192.168.0.10...
2023-05-04 19:31:22,260 snap7.common b' TCP : Unreachable peer'
2023-05-04 19:31:22,260 _plc_.client Не удалось подключиться к контроллеру: 192.168.0.10
Ошибка b' TCP : Unreachable peer' Traceback (most recent call last):
  File "D:\Work\DMU85\PLC_CV\python\plc.py", line 76, in run
    self.snap7client.connect(self.plc_ip, 0, 1)
  File "D:\Work\DMU85\PLC_CV\venv\lib\site-packages\snap7\client\__init__.py", line 24, in f
    check_error(code, context="client")
  File "D:\Work\DMU85\PLC_CV\venv\lib\site-packages\snap7\common.py", line 89, in check_error
    raise RuntimeError(error)
RuntimeError: b' TCP : Unreachable peer'

2023-05-04 19:32:22,435 _plc_.client Подключение к контроллеру 192.168.0.10...
2023-05-04 19:32:22,759 snap7.common b' TCP : Unreachable peer'
2023-05-04 19:32:22,760 _plc_.client Не удалось подключиться к контроллеру: 192.168.0.10
Ошибка b' TCP : Unreachable peer' Traceback (most recent call last):
  File "D:\Work\DMU85\PLC_CV\python\plc.py", line 76, in run
    self.snap7client.connect(self.plc_ip, 0, 1)
  File "D:\Work\DMU85\PLC_CV\venv\lib\site-packages\snap7\client\__init__.py", line 24, in f
    check_error(code, context="client")
  File "D:\Work\DMU85\PLC_CV\venv\lib\site-packages\snap7\common.py", line 89, in check_error
    raise RuntimeError(error)
RuntimeError: b' TCP : Unreachable peer'

2023-05-04 19:33:22,930 _plc_.client Подключение к контроллеру 192.168.0.10...
2023-05-04 19:33:23,254 snap7.common b' TCP : Unreachable peer'
2023-05-04 19:33:23,255 _plc_.client Не удалось подключиться к контроллеру: 192.168.0.10
Ошибка b' TCP : Unreachable peer' Traceback (most recent call last):
  File "D:\Work\DMU85\PLC_CV\python\plc.py", line 76, in run
    self.snap7client.connect(self.plc_ip, 0, 1)
  File "D:\Work\DMU85\PLC_CV\venv\lib\site-packages\snap7\client\__init__.py", line 24, in f
    check_error(code, context="client")
  File "D:\Work\DMU85\PLC_CV\venv\lib\site-packages\snap7\common.py", line 89, in check_error
    raise RuntimeError(error)
RuntimeError: b' TCP : Unreachable peer'

2023-05-04 19:34:23,418 _plc_.client Подключение к контроллеру 192.168.0.10...
2023-05-04 19:34:23,754 snap7.common b' TCP : Unreachable peer'
2023-05-04 19:34:23,755 _plc_.client Не удалось подключиться к контроллеру: 192.168.0.10
Ошибка b' TCP : Unreachable peer' Traceback (most recent call last):
  File "D:\Work\DMU85\PLC_CV\python\plc.py", line 76, in run
    self.snap7client.connect(self.plc_ip, 0, 1)
  File "D:\Work\DMU85\PLC_CV\venv\lib\site-packages\snap7\client\__init__.py", line 24, in f
    check_error(code, context="client")
  File "D:\Work\DMU85\PLC_CV\venv\lib\site-packages\snap7\common.py", line 89, in check_error
    raise RuntimeError(error)
RuntimeError: b' TCP : Unreachable peer'

2023-05-04 19:35:23,934 _plc_.client Подключение к контроллеру 192.168.0.10...
2023-05-04 19:35:24,263 snap7.common b' TCP : Unreachable peer'
2023-05-04 19:35:24,264 _plc_.client Не удалось подключиться к контроллеру: 192.168.0.10
Ошибка b' TCP : Unreachable peer' Traceback (most recent call last):
  File "D:\Work\DMU85\PLC_CV\python\plc.py", line 76, in run
    self.snap7client.connect(self.plc_ip, 0, 1)
  File "D:\Work\DMU85\PLC_CV\venv\lib\site-packages\snap7\client\__init__.py", line 24, in f
    check_error(code, context="client")
  File "D:\Work\DMU85\PLC_CV\venv\lib\site-packages\snap7\common.py", line 89, in check_error
    raise RuntimeError(error)
RuntimeError: b' TCP : Unreachable peer'

2023-05-04 19:36:24,441 _plc_.client Подключение к контроллеру 192.168.0.10...
2023-05-04 19:36:24,762 snap7.common b' TCP : Unreachable peer'
2023-05-04 19:36:24,763 _plc_.client Не удалось подключиться к контроллеру: 192.168.0.10
Ошибка b' TCP : Unreachable peer' Traceback (most recent call last):
  File "D:\Work\DMU85\PLC_CV\python\plc.py", line 76, in run
    self.snap7client.connect(self.plc_ip, 0, 1)
  File "D:\Work\DMU85\PLC_CV\venv\lib\site-packages\snap7\client\__init__.py", line 24, in f
    check_error(code, context="client")
  File "D:\Work\DMU85\PLC_CV\venv\lib\site-packages\snap7\common.py", line 89, in check_error
    raise RuntimeError(error)
RuntimeError: b' TCP : Unreachable peer'

2023-05-04 19:37:24,944 _plc_.client Подключение к контроллеру 192.168.0.10...
2023-05-04 19:37:25,259 snap7.common b' TCP : Unreachable peer'
2023-05-04 19:37:25,260 _plc_.client Не удалось подключиться к контроллеру: 192.168.0.10
Ошибка b' TCP : Unreachable peer' Traceback (most recent call last):
  File "D:\Work\DMU85\PLC_CV\python\plc.py", line 76, in run
    self.snap7client.connect(self.plc_ip, 0, 1)
  File "D:\Work\DMU85\PLC_CV\venv\lib\site-packages\snap7\client\__init__.py", line 24, in f
    check_error(code, context="client")
  File "D:\Work\DMU85\PLC_CV\venv\lib\site-packages\snap7\common.py", line 89, in check_error
    raise RuntimeError(error)
RuntimeError: b' TCP : Unreachable peer'

2023-05-04 19:38:25,428 _plc_.client Подключение к контроллеру 192.168.0.10...
2023-05-04 19:38:25,753 snap7.common b' TCP : Unreachable peer'
2023-05-04 19:38:25,754 _plc_.client Не удалось подключиться к контроллеру: 192.168.0.10
Ошибка b' TCP : Unreachable peer' Traceback (most recent call last):
  File "D:\Work\DMU85\PLC_CV\python\plc.py", line 76, in run
    self.snap7client.connect(self.plc_ip, 0, 1)
  File "D:\Work\DMU85\PLC_CV\venv\lib\site-packages\snap7\client\__init__.py", line 24, in f
    check_error(code, context="client")
  File "D:\Work\DMU85\PLC_CV\venv\lib\site-packages\snap7\common.py", line 89, in check_error
    raise RuntimeError(error)
RuntimeError: b' TCP : Unreachable peer'

2023-05-04 19:39:25,929 _plc_.client Подключение к контроллеру 192.168.0.10...
2023-05-04 19:39:26,260 snap7.common b' TCP : Unreachable peer'
2023-05-04 19:39:26,261 _plc_.client Не удалось подключиться к контроллеру: 192.168.0.10
Ошибка b' TCP : Unreachable peer' Traceback (most recent call last):
  File "D:\Work\DMU85\PLC_CV\python\plc.py", line 76, in run
    self.snap7client.connect(self.plc_ip, 0, 1)
  File "D:\Work\DMU85\PLC_CV\venv\lib\site-packages\snap7\client\__init__.py", line 24, in f
    check_error(code, context="client")
  File "D:\Work\DMU85\PLC_CV\venv\lib\site-packages\snap7\common.py", line 89, in check_error
    raise RuntimeError(error)
RuntimeError: b' TCP : Unreachable peer'

2023-05-04 19:40:26,431 _plc_.client Подключение к контроллеру 192.168.0.10...
2023-05-04 19:40:26,756 snap7.common b' TCP : Unreachable peer'
2023-05-04 19:40:26,757 _plc_.client Не удалось подключиться к контроллеру: 192.168.0.10
Ошибка b' TCP : Unreachable peer' Traceback (most recent call last):
  File "D:\Work\DMU85\PLC_CV\python\plc.py", line 76, in run
    self.snap7client.connect(self.plc_ip, 0, 1)
  File "D:\Work\DMU85\PLC_CV\venv\lib\site-packages\snap7\client\__init__.py", line 24, in f
    check_error(code, context="client")
  File "D:\Work\DMU85\PLC_CV\venv\lib\site-packages\snap7\common.py", line 89, in check_error
    raise RuntimeError(error)
RuntimeError: b' TCP : Unreachable peer'

2023-05-04 19:41:26,935 _plc_.client Подключение к контроллеру 192.168.0.10...
2023-05-04 19:41:27,256 snap7.common b' TCP : Unreachable peer'
2023-05-04 19:41:27,257 _plc_.client Не удалось подключиться к контроллеру: 192.168.0.10
Ошибка b' TCP : Unreachable peer' Traceback (most recent call last):
  File "D:\Work\DMU85\PLC_CV\python\plc.py", line 76, in run
    self.snap7client.connect(self.plc_ip, 0, 1)
  File "D:\Work\DMU85\PLC_CV\venv\lib\site-packages\snap7\client\__init__.py", line 24, in f
    check_error(code, context="client")
  File "D:\Work\DMU85\PLC_CV\venv\lib\site-packages\snap7\common.py", line 89, in check_error
    raise RuntimeError(error)
RuntimeError: b' TCP : Unreachable peer'

2023-05-04 19:42:27,432 _plc_.client Подключение к контроллеру 192.168.0.10...
2023-05-04 19:42:27,755 snap7.common b' TCP : Unreachable peer'
2023-05-04 19:42:27,756 _plc_.client Не удалось подключиться к контроллеру: 192.168.0.10
Ошибка b' TCP : Unreachable peer' Traceback (most recent call last):
  File "D:\Work\DMU85\PLC_CV\python\plc.py", line 76, in run
    self.snap7client.connect(self.plc_ip, 0, 1)
  File "D:\Work\DMU85\PLC_CV\venv\lib\site-packages\snap7\client\__init__.py", line 24, in f
    check_error(code, context="client")
  File "D:\Work\DMU85\PLC_CV\venv\lib\site-packages\snap7\common.py", line 89, in check_error
    raise RuntimeError(error)
RuntimeError: b' TCP : Unreachable peer'

2023-05-04 19:43:27,932 _plc_.client Подключение к контроллеру 192.168.0.10...
2023-05-04 19:43:28,256 snap7.common b' TCP : Unreachable peer'
2023-05-04 19:43:28,258 _plc_.client Не удалось подключиться к контроллеру: 192.168.0.10
Ошибка b' TCP : Unreachable peer' Traceback (most recent call last):
  File "D:\Work\DMU85\PLC_CV\python\plc.py", line 76, in run
    self.snap7client.connect(self.plc_ip, 0, 1)
  File "D:\Work\DMU85\PLC_CV\venv\lib\site-packages\snap7\client\__init__.py", line 24, in f
    check_error(code, context="client")
  File "D:\Work\DMU85\PLC_CV\venv\lib\site-packages\snap7\common.py", line 89, in check_error
    raise RuntimeError(error)
RuntimeError: b' TCP : Unreachable peer'

2023-05-04 19:44:28,440 _plc_.client Подключение к контроллеру 192.168.0.10...
2023-05-04 19:44:28,760 snap7.common b' TCP : Unreachable peer'
2023-05-04 19:44:28,760 _plc_.client Не удалось подключиться к контроллеру: 192.168.0.10
Ошибка b' TCP : Unreachable peer' Traceback (most recent call last):
  File "D:\Work\DMU85\PLC_CV\python\plc.py", line 76, in run
    self.snap7client.connect(self.plc_ip, 0, 1)
  File "D:\Work\DMU85\PLC_CV\venv\lib\site-packages\snap7\client\__init__.py", line 24, in f
    check_error(code, context="client")
  File "D:\Work\DMU85\PLC_CV\venv\lib\site-packages\snap7\common.py", line 89, in check_error
    raise RuntimeError(error)
RuntimeError: b' TCP : Unreachable peer'

2023-05-04 19:45:28,934 _plc_.client Подключение к контроллеру 192.168.0.10...
2023-05-04 19:45:29,262 snap7.common b' TCP : Unreachable peer'
2023-05-04 19:45:29,263 _plc_.client Не удалось подключиться к контроллеру: 192.168.0.10
Ошибка b' TCP : Unreachable peer' Traceback (most recent call last):
  File "D:\Work\DMU85\PLC_CV\python\plc.py", line 76, in run
    self.snap7client.connect(self.plc_ip, 0, 1)
  File "D:\Work\DMU85\PLC_CV\venv\lib\site-packages\snap7\client\__init__.py", line 24, in f
    check_error(code, context="client")
  File "D:\Work\DMU85\PLC_CV\venv\lib\site-packages\snap7\common.py", line 89, in check_error
    raise RuntimeError(error)
RuntimeError: b' TCP : Unreachable peer'

2023-05-04 19:46:29,432 _plc_.client Подключение к контроллеру 192.168.0.10...
2023-05-04 19:46:29,756 snap7.common b' TCP : Unreachable peer'
